(dp1
S'output'
p2
S'<type \'exceptions.RuntimeError\'> Failure to connect, tried 5 times:\nTraceback (most recent call last):\n  File "/home/nikhil/Documents/itws_2/web2py/gluon/dal.py", line 7845, in __init__\n    self._adapter = ADAPTERS[self._dbname](**kwargs)\n  File "/home/nikhil/Documents/itws_2/web2py/gluon/dal.py", line 688, in __call__\n    obj = super(AdapterMeta, cls).__call__(*args, **kwargs)\n  File "/home/nikhil/Documents/itws_2/web2py/gluon/dal.py", line 2413, in __init__\n    self.dbpath = uri.split(\'://\',1)[1]\nIndexError: list index out of range\n'
p3
sS'layer'
p4
S'/home/nikhil/Documents/itws_2/web2py/applications/nikhil/models/db.py'
p5
sS'code'
p6
S'db=DAL("sqlite:/storage.sqlite")\ndb.define_table(\'text\',Field(\'body\'),Field(\'data\'),Field(\'number\'))\n\n'
p7
sS'snapshot'
p8
(dp9
sS'traceback'
p10
S'Traceback (most recent call last):\n  File "/home/nikhil/Documents/itws_2/web2py/gluon/restricted.py", line 217, in restricted\n    exec ccode in environment\n  File "/home/nikhil/Documents/itws_2/web2py/applications/nikhil/models/db.py", line 1, in <module>\n    db=DAL("sqlite:/storage.sqlite")\n  File "/home/nikhil/Documents/itws_2/web2py/gluon/dal.py", line 7867, in __init__\n    raise RuntimeError("Failure to connect, tried %d times:\\n%s" % (attempts, tb))\nRuntimeError: Failure to connect, tried 5 times:\nTraceback (most recent call last):\n  File "/home/nikhil/Documents/itws_2/web2py/gluon/dal.py", line 7845, in __init__\n    self._adapter = ADAPTERS[self._dbname](**kwargs)\n  File "/home/nikhil/Documents/itws_2/web2py/gluon/dal.py", line 688, in __call__\n    obj = super(AdapterMeta, cls).__call__(*args, **kwargs)\n  File "/home/nikhil/Documents/itws_2/web2py/gluon/dal.py", line 2413, in __init__\n    self.dbpath = uri.split(\'://\',1)[1]\nIndexError: list index out of range\n\n'
p11
s.